<?xml version="1.0"?>
<sdf version="1.4">
  <model name="upcaroca">
    <!--Definition of the robot frame-->
    <link name="frame">
      <pose>0 0 0 0 0 0</pose>
      <inertial>
        <inertia>
          <ixx>100000</ixx>
          <iyy>100000</iyy>
          <izz>100000</izz>
          <ixy>0</ixy>
          <ixz>0</ixz>
          <iyz>0</iyz>
        </inertia>
        <mass>100000</mass>
      </inertial>
      <visual name="visual1">
        <geometry>
          <cylinder>
            <radius>0.02</radius>
            <length>3.48</length>
          </cylinder>
        </geometry>
        <pose>-4.000000 -2.100000 1.760000 0.000000 0.000000 0.000000</pose>
        <material>
          <script>
            <uri>file://media/materials/scripts/kitchen.material</uri>
            <name>Gazebo/Grey</name>
          </script>
        </material>
      </visual>
      <collision name="collision1">
        <geometry>
          <cylinder>
            <radius>0.02</radius>
          </cylinder>
        </geometry>
        <pose>-4.000000 -2.100000 1.760000 0.000000 0.000000 0.000000</pose>
      </collision>
      <visual name="visual2">
        <geometry>
          <cylinder>
            <radius>0.02</radius>
            <length>4.6</length>
          </cylinder>
        </geometry>
        <pose>-4.000000 0.200000 0.020000 1.570796 0.000000 0.000000</pose>
        <material>
          <script>
            <uri>file://media/materials/scripts/kitchen.material</uri>
            <name>Gazebo/Grey</name>
          </script>
        </material>
      </visual>
      <collision name="collision2">
        <geometry>
          <cylinder>
            <radius>0.02</radius>
          </cylinder>
        </geometry>
        <pose>-4.000000 0.200000 0.020000 1.570796 0.000000 0.000000</pose>
      </collision>
      <visual name="visual3">
        <geometry>
          <cylinder>
            <radius>0.02</radius>
            <length>8.0</length>
          </cylinder>
        </geometry>
        <pose>0.000000 -2.100000 0.020000 0.000000 1.570796 0.000000</pose>
        <material>
          <script>
            <uri>file://media/materials/scripts/kitchen.material</uri>
            <name>Gazebo/Grey</name>
          </script>
        </material>
      </visual>
      <collision name="collision3">
        <geometry>
          <cylinder>
            <radius>0.02</radius>
          </cylinder>
        </geometry>
        <pose>0.000000 -2.100000 0.020000 0.000000 1.570796 0.000000</pose>
      </collision>
      <visual name="visual4">
        <geometry>
          <cylinder>
            <radius>0.02</radius>
            <length>4.6</length>
          </cylinder>
        </geometry>
        <pose>-4.000000 0.200000 3.500000 1.570796 0.000000 0.000000</pose>
        <material>
          <script>
            <uri>file://media/materials/scripts/kitchen.material</uri>
            <name>Gazebo/Grey</name>
          </script>
        </material>
      </visual>
      <collision name="collision4">
        <geometry>
          <cylinder>
            <radius>0.02</radius>
          </cylinder>
        </geometry>
        <pose>-4.000000 0.200000 3.500000 1.570796 0.000000 0.000000</pose>
      </collision>
      <visual name="visual5">
        <geometry>
          <cylinder>
            <radius>0.02</radius>
            <length>8.0</length>
          </cylinder>
        </geometry>
        <pose>0.000000 -2.100000 3.500000 0.000000 1.570796 0.000000</pose>
        <material>
          <script>
            <uri>file://media/materials/scripts/kitchen.material</uri>
            <name>Gazebo/Grey</name>
          </script>
        </material>
      </visual>
      <collision name="collision5">
        <geometry>
          <cylinder>
            <radius>0.02</radius>
          </cylinder>
        </geometry>
        <pose>0.000000 -2.100000 3.500000 0.000000 1.570796 0.000000</pose>
      </collision>
      <visual name="visual6">
        <geometry>
          <cylinder>
            <radius>0.02</radius>
            <length>3.48</length>
          </cylinder>
        </geometry>
        <pose>-4.000000 2.500000 1.760000 0.000000 0.000000 0.000000</pose>
        <material>
          <script>
            <uri>file://media/materials/scripts/kitchen.material</uri>
            <name>Gazebo/Grey</name>
          </script>
        </material>
      </visual>
      <collision name="collision6">
        <geometry>
          <cylinder>
            <radius>0.02</radius>
          </cylinder>
        </geometry>
        <pose>-4.000000 2.500000 1.760000 0.000000 0.000000 0.000000</pose>
      </collision>
      <visual name="visual7">
        <geometry>
          <cylinder>
            <radius>0.02</radius>
            <length>8.0</length>
          </cylinder>
        </geometry>
        <pose>0.000000 2.500000 0.020000 0.000000 1.570796 0.000000</pose>
        <material>
          <script>
            <uri>file://media/materials/scripts/kitchen.material</uri>
            <name>Gazebo/Grey</name>
          </script>
        </material>
      </visual>
      <collision name="collision7">
        <geometry>
          <cylinder>
            <radius>0.02</radius>
          </cylinder>
        </geometry>
        <pose>0.000000 2.500000 0.020000 0.000000 1.570796 0.000000</pose>
      </collision>
      <visual name="visual8">
        <geometry>
          <cylinder>
            <radius>0.02</radius>
            <length>8.0</length>
          </cylinder>
        </geometry>
        <pose>0.000000 2.500000 3.500000 0.000000 1.570796 0.000000</pose>
        <material>
          <script>
            <uri>file://media/materials/scripts/kitchen.material</uri>
            <name>Gazebo/Grey</name>
          </script>
        </material>
      </visual>
      <collision name="collision8">
        <geometry>
          <cylinder>
            <radius>0.02</radius>
          </cylinder>
        </geometry>
        <pose>0.000000 2.500000 3.500000 0.000000 1.570796 0.000000</pose>
      </collision>
      <visual name="visual9">
        <geometry>
          <cylinder>
            <radius>0.02</radius>
            <length>3.48</length>
          </cylinder>
        </geometry>
        <pose>4.000000 -2.100000 1.760000 0.000000 0.000000 0.000000</pose>
        <material>
          <script>
            <uri>file://media/materials/scripts/kitchen.material</uri>
            <name>Gazebo/Grey</name>
          </script>
        </material>
      </visual>
      <collision name="collision9">
        <geometry>
          <cylinder>
            <radius>0.02</radius>
          </cylinder>
        </geometry>
        <pose>4.000000 -2.100000 1.760000 0.000000 0.000000 0.000000</pose>
      </collision>
      <visual name="visual10">
        <geometry>
          <cylinder>
            <radius>0.02</radius>
            <length>4.6</length>
          </cylinder>
        </geometry>
        <pose>4.000000 0.200000 0.020000 1.570796 0.000000 0.000000</pose>
        <material>
          <script>
            <uri>file://media/materials/scripts/kitchen.material</uri>
            <name>Gazebo/Grey</name>
          </script>
        </material>
      </visual>
      <collision name="collision10">
        <geometry>
          <cylinder>
            <radius>0.02</radius>
          </cylinder>
        </geometry>
        <pose>4.000000 0.200000 0.020000 1.570796 0.000000 0.000000</pose>
      </collision>
      <visual name="visual11">
        <geometry>
          <cylinder>
            <radius>0.02</radius>
            <length>4.6</length>
          </cylinder>
        </geometry>
        <pose>4.000000 0.200000 3.500000 1.570796 0.000000 0.000000</pose>
        <material>
          <script>
            <uri>file://media/materials/scripts/kitchen.material</uri>
            <name>Gazebo/Grey</name>
          </script>
        </material>
      </visual>
      <collision name="collision11">
        <geometry>
          <cylinder>
            <radius>0.02</radius>
          </cylinder>
        </geometry>
        <pose>4.000000 0.200000 3.500000 1.570796 0.000000 0.000000</pose>
      </collision>
      <visual name="visual12">
        <geometry>
          <cylinder>
            <radius>0.02</radius>
            <length>3.48</length>
          </cylinder>
        </geometry>
        <pose>4.000000 2.500000 1.760000 0.000000 0.000000 0.000000</pose>
        <material>
          <script>
            <uri>file://media/materials/scripts/kitchen.material</uri>
            <name>Gazebo/Grey</name>
          </script>
        </material>
      </visual>
      <collision name="collision12">
        <geometry>
          <cylinder>
            <radius>0.02</radius>
          </cylinder>
        </geometry>
        <pose>4.000000 2.500000 1.760000 0.000000 0.000000 0.000000</pose>
      </collision>
    </link>
    <!--Definition of the robot cables-->
    <!--Definition of the robot platform-->
    <link name="platform">
      <pose>0.900000 0.900000 1.800000 0.000000 0.000000 0.000000</pose>
      <visual name="visualpf">
        <geometry>
          <box>
            <size>1.200000 0.600000 0.400000</size>
          </box>
        </geometry>
        <material>
          <script>
            <uri>file://media/materials/scripts/kitchen.material</uri>
            <name>Gazebo/Blue</name>
          </script>
        </material>
      </visual>
      <collision name="collisionpf">
        <geometry>
          <box>
            <size>1.200000 0.600000 0.400000</size>
          </box>
        </geometry>
      </collision>
      <inertial>
        <inertia>
          <ixx>6.5</ixx>
          <iyy>20.0</iyy>
          <izz>22.5</izz>
          <ixy>0.0</ixy>
          <ixz>0.0</ixz>
          <iyz>0.0</iyz>
        </inertia>
        <mass>57</mass>
      </inertial>
    </link>
    <link name="cable0">
      <pose>-2.645843 -1.555838 3.175420 -2.201876 0.998615 -1.642199</pose>
      <visual name="visual">
        <geometry>
          <cylinder>
            <radius>0.005</radius>
            <length>9.862575728479857</length>
          </cylinder>
        </geometry>
        <material>
          <script>
            <uri>file://media/materials/scripts/kitchen.material</uri>
            <name>Gazebo/Black</name>
          </script>
        </material>
      </visual>
      <inertial>
        <inertia>
          <ixx>0.001</ixx>
          <iyy>0.001</iyy>
          <izz>0.001</izz>
          <ixy>0</ixy>
          <ixz>0</ixz>
          <iyz>0</iyz>
        </inertia>
        <mass>0.001</mass>
      </inertial>
    </link>
    <link name="virt_X0">
      <inertial>
        <inertia>
          <ixx>0.001</ixx>
          <iyy>0.001</iyy>
          <izz>0.001</izz>
          <ixy>0</ixy>
          <ixz>0</ixz>
          <iyz>0</iyz>
        </inertia>
        <mass>0.001</mass>
      </inertial>
      <pose>-3.500000 -2.000000 3.500000 -2.201876 0.998615 -1.642199</pose>
    </link>
    <joint name="rev_X0" type="revolute">
      <pose>0 0 0 -2.201876 0.998615 -1.642199</pose>
      <parent>frame</parent>
      <child>virt_X0</child>
      <axis>
        <xyz>-0.038629 -0.540087 -0.840722</xyz>
        <limit>
          <effort>1000</effort>
          <velocity>10</velocity>
        </limit>
        <dynamics>
          <damping>0.01</damping>
        </dynamics>
      </axis>
    </joint>
    <link name="virt_Y0">
      <inertial>
        <inertia>
          <ixx>0.001</ixx>
          <iyy>0.001</iyy>
          <izz>0.001</izz>
          <ixy>0</ixy>
          <ixz>0</ixz>
          <iyz>0</iyz>
        </inertia>
        <mass>0.001</mass>
      </inertial>
      <pose>-3.500000 -2.000000 3.500000 -2.201876 0.998615 -1.642199</pose>
    </link>
    <joint name="rev_Y0" type="revolute">
      <pose>0 0 0 -2.201876 0.998615 -1.642199</pose>
      <parent>virt_X0</parent>
      <child>virt_Y0</child>
      <axis>
        <xyz>-0.540087 0.719155 -0.437176</xyz>
        <limit>
          <effort>1000</effort>
          <velocity>10</velocity>
        </limit>
        <dynamics>
          <damping>0.01</damping>
        </dynamics>
      </axis>
    </joint>
    <joint name="cable0" type="prismatic">
      <pose>0 0 -0.842419 -2.201876 0.998615 -1.642199</pose>
      <parent>virt_Y0</parent>
      <child>cable0</child>
      <axis>
        <xyz>-0.840722 -0.437176 0.319474</xyz>
        <limit>
          <lower>-4.931287864239929</lower>
          <upper>4.931287864239929</upper>
          <effort>10000</effort>
          <velocity>10</velocity>
        </limit>
        <dynamics>
          <damping>1</damping>
        </dynamics>
      </axis>
    </joint>
    <link name="virt_Xpf0">
      <inertial>
        <inertia>
          <ixx>0.001</ixx>
          <iyy>0.001</iyy>
          <izz>0.001</izz>
          <ixy>0</ixy>
          <ixz>0</ixz>
          <iyz>0</iyz>
        </inertia>
        <mass>0.001</mass>
      </inertial>
      <pose>1.500000 0.600000 1.600000 -2.201876 0.998615 -1.642199</pose>
    </link>
    <joint name="rev_Xpf0" type="revolute">
      <pose>0 0 0 -2.201876 0.998615 -1.642199</pose>
      <parent>platform</parent>
      <child>virt_Xpf0</child>
      <axis>
        <xyz>1 0 0</xyz>
        <limit>
          <effort>1000</effort>
          <velocity>10</velocity>
        </limit>
        <dynamics>
          <damping>0.01</damping>
        </dynamics>
      </axis>
    </joint>
    <link name="virt_Ypf0">
      <inertial>
        <inertia>
          <ixx>0.001</ixx>
          <iyy>0.001</iyy>
          <izz>0.001</izz>
          <ixy>0</ixy>
          <ixz>0</ixz>
          <iyz>0</iyz>
        </inertia>
        <mass>0.001</mass>
      </inertial>
      <pose>1.500000 0.600000 1.600000 -2.201876 0.998615 -1.642199</pose>
    </link>
    <joint name="rev_Ypf0" type="revolute">
      <pose>0 0 0 -2.201876 0.998615 -1.642199</pose>
      <parent>virt_Xpf0</parent>
      <child>virt_Ypf0</child>
      <axis>
        <xyz>0 1 0</xyz>
        <limit>
          <effort>1000</effort>
          <velocity>10</velocity>
        </limit>
        <dynamics>
          <damping>0.01</damping>
        </dynamics>
      </axis>
    </joint>
    <joint name="rev_Zpf0" type="revolute">
      <pose>0 0 0 -2.201876 0.998615 -1.642199</pose>
      <child>virt_Ypf0</child>
      <parent>cable0</parent>
      <axis>
        <xyz>0 0 1</xyz>
        <limit>
          <effort>1000</effort>
          <velocity>10</velocity>
        </limit>
        <dynamics>
          <damping>0.01</damping>
        </dynamics>
      </axis>
    </joint>
    <link name="cable1">
      <pose>-3.310986 -1.840830 3.425389 -2.009133 0.821635 -1.201550</pose>
      <visual name="visual">
        <geometry>
          <cylinder>
            <radius>0.005</radius>
            <length>9.862575728479857</length>
          </cylinder>
        </geometry>
        <material>
          <script>
            <uri>file://media/materials/scripts/kitchen.material</uri>
            <name>Gazebo/Black</name>
          </script>
        </material>
      </visual>
      <inertial>
        <inertia>
          <ixx>0.001</ixx>
          <iyy>0.001</iyy>
          <izz>0.001</izz>
          <ixy>0</ixy>
          <ixz>0</ixz>
          <iyz>0</iyz>
        </inertia>
        <mass>0.001</mass>
      </inertial>
    </link>
    <link name="virt_X1">
      <inertial>
        <inertia>
          <ixx>0.001</ixx>
          <iyy>0.001</iyy>
          <izz>0.001</izz>
          <ixy>0</ixy>
          <ixz>0</ixz>
          <iyz>0</iyz>
        </inertia>
        <mass>0.001</mass>
      </inertial>
      <pose>-3.500000 -2.000000 3.500000 -2.009133 0.821635 -1.201550</pose>
    </link>
    <joint name="rev_X1" type="revolute">
      <pose>0 0 0 -2.009133 0.821635 -1.201550</pose>
      <parent>frame</parent>
      <child>virt_X1</child>
      <axis>
        <xyz>0.245791 -0.635124 -0.732260</xyz>
        <limit>
          <effort>1000</effort>
          <velocity>10</velocity>
        </limit>
        <dynamics>
          <damping>0.01</damping>
        </dynamics>
      </axis>
    </joint>
    <link name="virt_Y1">
      <inertial>
        <inertia>
          <ixx>0.001</ixx>
          <iyy>0.001</iyy>
          <izz>0.001</izz>
          <ixy>0</ixy>
          <ixz>0</ixz>
          <iyz>0</iyz>
        </inertia>
        <mass>0.001</mass>
      </inertial>
      <pose>-3.500000 -2.000000 3.500000 -2.009133 0.821635 -1.201550</pose>
    </link>
    <joint name="rev_Y1" type="revolute">
      <pose>0 0 0 -2.009133 0.821635 -1.201550</pose>
      <parent>virt_X1</parent>
      <child>virt_Y1</child>
      <axis>
        <xyz>-0.635124 0.465159 -0.616640</xyz>
        <limit>
          <effort>1000</effort>
          <velocity>10</velocity>
        </limit>
        <dynamics>
          <damping>0.01</damping>
        </dynamics>
      </axis>
    </joint>
    <joint name="cable1" type="prismatic">
      <pose>0 0 -0.245285 -2.009133 0.821635 -1.201550</pose>
      <parent>virt_Y1</parent>
      <child>cable1</child>
      <axis>
        <xyz>-0.732260 -0.616640 0.289050</xyz>
        <limit>
          <lower>-4.931287864239929</lower>
          <upper>4.931287864239929</upper>
          <effort>10000</effort>
          <velocity>10</velocity>
        </limit>
        <dynamics>
          <damping>1</damping>
        </dynamics>
      </axis>
    </joint>
    <link name="virt_Xpf1">
      <inertial>
        <inertia>
          <ixx>0.001</ixx>
          <iyy>0.001</iyy>
          <izz>0.001</izz>
          <ixy>0</ixy>
          <ixz>0</ixz>
          <iyz>0</iyz>
        </inertia>
        <mass>0.001</mass>
      </inertial>
      <pose>0.300000 1.200000 2.000000 -2.009133 0.821635 -1.201550</pose>
    </link>
    <joint name="rev_Xpf1" type="revolute">
      <pose>0 0 0 -2.009133 0.821635 -1.201550</pose>
      <parent>platform</parent>
      <child>virt_Xpf1</child>
      <axis>
        <xyz>1 0 0</xyz>
        <limit>
          <effort>1000</effort>
          <velocity>10</velocity>
        </limit>
        <dynamics>
          <damping>0.01</damping>
        </dynamics>
      </axis>
    </joint>
    <link name="virt_Ypf1">
      <inertial>
        <inertia>
          <ixx>0.001</ixx>
          <iyy>0.001</iyy>
          <izz>0.001</izz>
          <ixy>0</ixy>
          <ixz>0</ixz>
          <iyz>0</iyz>
        </inertia>
        <mass>0.001</mass>
      </inertial>
      <pose>0.300000 1.200000 2.000000 -2.009133 0.821635 -1.201550</pose>
    </link>
    <joint name="rev_Ypf1" type="revolute">
      <pose>0 0 0 -2.009133 0.821635 -1.201550</pose>
      <parent>virt_Xpf1</parent>
      <child>virt_Ypf1</child>
      <axis>
        <xyz>0 1 0</xyz>
        <limit>
          <effort>1000</effort>
          <velocity>10</velocity>
        </limit>
        <dynamics>
          <damping>0.01</damping>
        </dynamics>
      </axis>
    </joint>
    <joint name="rev_Zpf1" type="revolute">
      <pose>0 0 0 -2.009133 0.821635 -1.201550</pose>
      <child>virt_Ypf1</child>
      <parent>cable1</parent>
      <axis>
        <xyz>0 0 1</xyz>
        <limit>
          <effort>1000</effort>
          <velocity>10</velocity>
        </limit>
        <dynamics>
          <damping>0.01</damping>
        </dynamics>
      </axis>
    </joint>
    <link name="cable2">
      <pose>3.896623 -2.322257 3.685917 -2.094075 -0.817368 1.286769</pose>
      <visual name="visual">
        <geometry>
          <cylinder>
            <radius>0.005</radius>
            <length>9.862575728479857</length>
          </cylinder>
        </geometry>
        <material>
          <script>
            <uri>file://media/materials/scripts/kitchen.material</uri>
            <name>Gazebo/Black</name>
          </script>
        </material>
      </visual>
      <inertial>
        <inertia>
          <ixx>0.001</ixx>
          <iyy>0.001</iyy>
          <izz>0.001</izz>
          <ixy>0</ixy>
          <ixz>0</ixz>
          <iyz>0</iyz>
        </inertia>
        <mass>0.001</mass>
      </inertial>
    </link>
    <link name="virt_X2">
      <inertial>
        <inertia>
          <ixx>0.001</ixx>
          <iyy>0.001</iyy>
          <izz>0.001</izz>
          <ixy>0</ixy>
          <ixz>0</ixz>
          <iyz>0</iyz>
        </inertia>
        <mass>0.001</mass>
      </inertial>
      <pose>3.500000 -2.000000 3.500000 -2.094075 -0.817368 1.286769</pose>
    </link>
    <joint name="rev_X2" type="revolute">
      <pose>0 0 0 -2.094075 -0.817368 1.286769</pose>
      <parent>frame</parent>
      <child>virt_X2</child>
      <axis>
        <xyz>0.191714 0.656733 0.729348</xyz>
        <limit>
          <effort>1000</effort>
          <velocity>10</velocity>
        </limit>
        <dynamics>
          <damping>0.01</damping>
        </dynamics>
      </axis>
    </joint>
    <link name="virt_Y2">
      <inertial>
        <inertia>
          <ixx>0.001</ixx>
          <iyy>0.001</iyy>
          <izz>0.001</izz>
          <ixy>0</ixy>
          <ixz>0</ixz>
          <iyz>0</iyz>
        </inertia>
        <mass>0.001</mass>
      </inertial>
      <pose>3.500000 -2.000000 3.500000 -2.094075 -0.817368 1.286769</pose>
    </link>
    <joint name="rev_Y2" type="revolute">
      <pose>0 0 0 -2.094075 -0.817368 1.286769</pose>
      <parent>virt_X2</parent>
      <child>virt_Y2</child>
      <axis>
        <xyz>0.656733 0.466405 -0.592595</xyz>
        <limit>
          <effort>1000</effort>
          <velocity>10</velocity>
        </limit>
        <dynamics>
          <damping>0.01</damping>
        </dynamics>
      </axis>
    </joint>
    <joint name="cable2" type="prismatic">
      <pose>0 0 0.611208 -2.094075 -0.817368 1.286769</pose>
      <parent>virt_Y2</parent>
      <child>cable2</child>
      <axis>
        <xyz>0.729348 -0.592595 0.341882</xyz>
        <limit>
          <lower>-4.931287864239929</lower>
          <upper>4.931287864239929</upper>
          <effort>10000</effort>
          <velocity>10</velocity>
        </limit>
        <dynamics>
          <damping>1</damping>
        </dynamics>
      </axis>
    </joint>
    <link name="virt_Xpf2">
      <inertial>
        <inertia>
          <ixx>0.001</ixx>
          <iyy>0.001</iyy>
          <izz>0.001</izz>
          <ixy>0</ixy>
          <ixz>0</ixz>
          <iyz>0</iyz>
        </inertia>
        <mass>0.001</mass>
      </inertial>
      <pose>0.300000 0.600000 2.000000 -2.094075 -0.817368 1.286769</pose>
    </link>
    <joint name="rev_Xpf2" type="revolute">
      <pose>0 0 0 -2.094075 -0.817368 1.286769</pose>
      <parent>platform</parent>
      <child>virt_Xpf2</child>
      <axis>
        <xyz>1 0 0</xyz>
        <limit>
          <effort>1000</effort>
          <velocity>10</velocity>
        </limit>
        <dynamics>
          <damping>0.01</damping>
        </dynamics>
      </axis>
    </joint>
    <link name="virt_Ypf2">
      <inertial>
        <inertia>
          <ixx>0.001</ixx>
          <iyy>0.001</iyy>
          <izz>0.001</izz>
          <ixy>0</ixy>
          <ixz>0</ixz>
          <iyz>0</iyz>
        </inertia>
        <mass>0.001</mass>
      </inertial>
      <pose>0.300000 0.600000 2.000000 -2.094075 -0.817368 1.286769</pose>
    </link>
    <joint name="rev_Ypf2" type="revolute">
      <pose>0 0 0 -2.094075 -0.817368 1.286769</pose>
      <parent>virt_Xpf2</parent>
      <child>virt_Ypf2</child>
      <axis>
        <xyz>0 1 0</xyz>
        <limit>
          <effort>1000</effort>
          <velocity>10</velocity>
        </limit>
        <dynamics>
          <damping>0.01</damping>
        </dynamics>
      </axis>
    </joint>
    <joint name="rev_Zpf2" type="revolute">
      <pose>0 0 0 -2.094075 -0.817368 1.286769</pose>
      <child>virt_Ypf2</child>
      <parent>cable2</parent>
      <axis>
        <xyz>0 0 1</xyz>
        <limit>
          <effort>1000</effort>
          <velocity>10</velocity>
        </limit>
        <dynamics>
          <damping>0.01</damping>
        </dynamics>
      </axis>
    </joint>
    <link name="cable3">
      <pose>3.834378 -2.535005 3.817659 -2.106608 -0.493125 0.832600</pose>
      <visual name="visual">
        <geometry>
          <cylinder>
            <radius>0.005</radius>
            <length>9.862575728479857</length>
          </cylinder>
        </geometry>
        <material>
          <script>
            <uri>file://media/materials/scripts/kitchen.material</uri>
            <name>Gazebo/Black</name>
          </script>
        </material>
      </visual>
      <inertial>
        <inertia>
          <ixx>0.001</ixx>
          <iyy>0.001</iyy>
          <izz>0.001</izz>
          <ixy>0</ixy>
          <ixz>0</ixz>
          <iyz>0</iyz>
        </inertia>
        <mass>0.001</mass>
      </inertial>
    </link>
    <link name="virt_X3">
      <inertial>
        <inertia>
          <ixx>0.001</ixx>
          <iyy>0.001</iyy>
          <izz>0.001</izz>
          <ixy>0</ixy>
          <ixz>0</ixz>
          <iyz>0</iyz>
        </inertia>
        <mass>0.001</mass>
      </inertial>
      <pose>3.500000 -2.000000 3.500000 -2.106608 -0.493125 0.832600</pose>
    </link>
    <joint name="rev_X3" type="revolute">
      <pose>0 0 0 -2.106608 -0.493125 0.832600</pose>
      <parent>frame</parent>
      <child>virt_X3</child>
      <axis>
        <xyz>0.592778 0.651556 0.473381</xyz>
        <limit>
          <effort>1000</effort>
          <velocity>10</velocity>
        </limit>
        <dynamics>
          <damping>0.01</damping>
        </dynamics>
      </axis>
    </joint>
    <link name="virt_Y3">
      <inertial>
        <inertia>
          <ixx>0.001</ixx>
          <iyy>0.001</iyy>
          <izz>0.001</izz>
          <ixy>0</ixy>
          <ixz>0</ixz>
          <iyz>0</iyz>
        </inertia>
        <mass>0.001</mass>
      </inertial>
      <pose>3.500000 -2.000000 3.500000 -2.106608 -0.493125 0.832600</pose>
    </link>
    <joint name="rev_Y3" type="revolute">
      <pose>0 0 0 -2.106608 -0.493125 0.832600</pose>
      <parent>virt_X3</parent>
      <child>virt_Y3</child>
      <axis>
        <xyz>0.651556 -0.042490 -0.757410</xyz>
        <limit>
          <effort>1000</effort>
          <velocity>10</velocity>
        </limit>
        <dynamics>
          <damping>0.01</damping>
        </dynamics>
      </axis>
    </joint>
    <joint name="cable3" type="prismatic">
      <pose>0 0 0.824458 -2.106608 -0.493125 0.832600</pose>
      <parent>virt_Y3</parent>
      <child>cable3</child>
      <axis>
        <xyz>0.473381 -0.757410 0.449712</xyz>
        <limit>
          <lower>-4.931287864239929</lower>
          <upper>4.931287864239929</upper>
          <effort>10000</effort>
          <velocity>10</velocity>
        </limit>
        <dynamics>
          <damping>1</damping>
        </dynamics>
      </axis>
    </joint>
    <link name="virt_Xpf3">
      <inertial>
        <inertia>
          <ixx>0.001</ixx>
          <iyy>0.001</iyy>
          <izz>0.001</izz>
          <ixy>0</ixy>
          <ixz>0</ixz>
          <iyz>0</iyz>
        </inertia>
        <mass>0.001</mass>
      </inertial>
      <pose>1.500000 1.200000 1.600000 -2.106608 -0.493125 0.832600</pose>
    </link>
    <joint name="rev_Xpf3" type="revolute">
      <pose>0 0 0 -2.106608 -0.493125 0.832600</pose>
      <parent>platform</parent>
      <child>virt_Xpf3</child>
      <axis>
        <xyz>1 0 0</xyz>
        <limit>
          <effort>1000</effort>
          <velocity>10</velocity>
        </limit>
        <dynamics>
          <damping>0.01</damping>
        </dynamics>
      </axis>
    </joint>
    <link name="virt_Ypf3">
      <inertial>
        <inertia>
          <ixx>0.001</ixx>
          <iyy>0.001</iyy>
          <izz>0.001</izz>
          <ixy>0</ixy>
          <ixz>0</ixz>
          <iyz>0</iyz>
        </inertia>
        <mass>0.001</mass>
      </inertial>
      <pose>1.500000 1.200000 1.600000 -2.106608 -0.493125 0.832600</pose>
    </link>
    <joint name="rev_Ypf3" type="revolute">
      <pose>0 0 0 -2.106608 -0.493125 0.832600</pose>
      <parent>virt_Xpf3</parent>
      <child>virt_Ypf3</child>
      <axis>
        <xyz>0 1 0</xyz>
        <limit>
          <effort>1000</effort>
          <velocity>10</velocity>
        </limit>
        <dynamics>
          <damping>0.01</damping>
        </dynamics>
      </axis>
    </joint>
    <joint name="rev_Zpf3" type="revolute">
      <pose>0 0 0 -2.106608 -0.493125 0.832600</pose>
      <child>virt_Ypf3</child>
      <parent>cable3</parent>
      <axis>
        <xyz>0 0 1</xyz>
        <limit>
          <effort>1000</effort>
          <velocity>10</velocity>
        </limit>
        <dynamics>
          <damping>0.01</damping>
        </dynamics>
      </axis>
    </joint>
    <link name="cable4">
      <pose>-3.889097 2.143351 3.694548 2.506566 1.015025 2.074099</pose>
      <visual name="visual">
        <geometry>
          <cylinder>
            <radius>0.005</radius>
            <length>9.862575728479857</length>
          </cylinder>
        </geometry>
        <material>
          <script>
            <uri>file://media/materials/scripts/kitchen.material</uri>
            <name>Gazebo/Black</name>
          </script>
        </material>
      </visual>
      <inertial>
        <inertia>
          <ixx>0.001</ixx>
          <iyy>0.001</iyy>
          <izz>0.001</izz>
          <ixy>0</ixy>
          <ixz>0</ixz>
          <iyz>0</iyz>
        </inertia>
        <mass>0.001</mass>
      </inertial>
    </link>
    <link name="virt_X4">
      <inertial>
        <inertia>
          <ixx>0.001</ixx>
          <iyy>0.001</iyy>
          <izz>0.001</izz>
          <ixy>0</ixy>
          <ixz>0</ixz>
          <iyz>0</iyz>
        </inertia>
        <mass>0.001</mass>
      </inertial>
      <pose>-3.500000 2.000000 3.500000 2.506566 1.015025 2.074099</pose>
    </link>
    <joint name="rev_X4" type="revolute">
      <pose>0 0 0 2.506566 1.015025 2.074099</pose>
      <parent>frame</parent>
      <child>virt_X4</child>
      <axis>
        <xyz>-0.254472 0.462174 -0.849493</xyz>
        <limit>
          <effort>1000</effort>
          <velocity>10</velocity>
        </limit>
        <dynamics>
          <damping>0.01</damping>
        </dynamics>
      </axis>
    </joint>
    <link name="virt_Y4">
      <inertial>
        <inertia>
          <ixx>0.001</ixx>
          <iyy>0.001</iyy>
          <izz>0.001</izz>
          <ixy>0</ixy>
          <ixz>0</ixz>
          <iyz>0</iyz>
        </inertia>
        <mass>0.001</mass>
      </inertial>
      <pose>-3.500000 2.000000 3.500000 2.506566 1.015025 2.074099</pose>
    </link>
    <joint name="rev_Y4" type="revolute">
      <pose>0 0 0 2.506566 1.015025 2.074099</pose>
      <parent>virt_X4</parent>
      <child>virt_Y4</child>
      <axis>
        <xyz>0.462174 0.829725 0.312971</xyz>
        <limit>
          <effort>1000</effort>
          <velocity>10</velocity>
        </limit>
        <dynamics>
          <damping>0.01</damping>
        </dynamics>
      </axis>
    </joint>
    <joint name="cable4" type="prismatic">
      <pose>0 0 0.504934 2.506566 1.015025 2.074099</pose>
      <parent>virt_Y4</parent>
      <child>cable4</child>
      <axis>
        <xyz>-0.849493 0.312971 0.424747</xyz>
        <limit>
          <lower>-4.931287864239929</lower>
          <upper>4.931287864239929</upper>
          <effort>10000</effort>
          <velocity>10</velocity>
        </limit>
        <dynamics>
          <damping>1</damping>
        </dynamics>
      </axis>
    </joint>
    <link name="virt_Xpf4">
      <inertial>
        <inertia>
          <ixx>0.001</ixx>
          <iyy>0.001</iyy>
          <izz>0.001</izz>
          <ixy>0</ixy>
          <ixz>0</ixz>
          <iyz>0</iyz>
        </inertia>
        <mass>0.001</mass>
      </inertial>
      <pose>0.300000 0.600000 1.600000 2.506566 1.015025 2.074099</pose>
    </link>
    <joint name="rev_Xpf4" type="revolute">
      <pose>0 0 0 2.506566 1.015025 2.074099</pose>
      <parent>platform</parent>
      <child>virt_Xpf4</child>
      <axis>
        <xyz>1 0 0</xyz>
        <limit>
          <effort>1000</effort>
          <velocity>10</velocity>
        </limit>
        <dynamics>
          <damping>0.01</damping>
        </dynamics>
      </axis>
    </joint>
    <link name="virt_Ypf4">
      <inertial>
        <inertia>
          <ixx>0.001</ixx>
          <iyy>0.001</iyy>
          <izz>0.001</izz>
          <ixy>0</ixy>
          <ixz>0</ixz>
          <iyz>0</iyz>
        </inertia>
        <mass>0.001</mass>
      </inertial>
      <pose>0.300000 0.600000 1.600000 2.506566 1.015025 2.074099</pose>
    </link>
    <joint name="rev_Ypf4" type="revolute">
      <pose>0 0 0 2.506566 1.015025 2.074099</pose>
      <parent>virt_Xpf4</parent>
      <child>virt_Ypf4</child>
      <axis>
        <xyz>0 1 0</xyz>
        <limit>
          <effort>1000</effort>
          <velocity>10</velocity>
        </limit>
        <dynamics>
          <damping>0.01</damping>
        </dynamics>
      </axis>
    </joint>
    <joint name="rev_Zpf4" type="revolute">
      <pose>0 0 0 2.506566 1.015025 2.074099</pose>
      <child>virt_Ypf4</child>
      <parent>cable4</parent>
      <axis>
        <xyz>0 0 1</xyz>
        <limit>
          <effort>1000</effort>
          <velocity>10</velocity>
        </limit>
        <dynamics>
          <damping>0.01</damping>
        </dynamics>
      </axis>
    </joint>
    <link name="cable5">
      <pose>-3.168809 1.947009 3.400643 2.651635 1.243058 2.469927</pose>
      <visual name="visual">
        <geometry>
          <cylinder>
            <radius>0.005</radius>
            <length>9.862575728479857</length>
          </cylinder>
        </geometry>
        <material>
          <script>
            <uri>file://media/materials/scripts/kitchen.material</uri>
            <name>Gazebo/Black</name>
          </script>
        </material>
      </visual>
      <inertial>
        <inertia>
          <ixx>0.001</ixx>
          <iyy>0.001</iyy>
          <izz>0.001</izz>
          <ixy>0</ixy>
          <ixz>0</ixz>
          <iyz>0</iyz>
        </inertia>
        <mass>0.001</mass>
      </inertial>
    </link>
    <link name="virt_X5">
      <inertial>
        <inertia>
          <ixx>0.001</ixx>
          <iyy>0.001</iyy>
          <izz>0.001</izz>
          <ixy>0</ixy>
          <ixz>0</ixz>
          <iyz>0</iyz>
        </inertia>
        <mass>0.001</mass>
      </inertial>
      <pose>-3.500000 2.000000 3.500000 2.651635 1.243058 2.469927</pose>
    </link>
    <joint name="rev_X5" type="revolute">
      <pose>0 0 0 2.651635 1.243058 2.469927</pose>
      <parent>frame</parent>
      <child>virt_X5</child>
      <axis>
        <xyz>-0.251981 0.200317 -0.946773</xyz>
        <limit>
          <effort>1000</effort>
          <velocity>10</velocity>
        </limit>
        <dynamics>
          <damping>0.01</damping>
        </dynamics>
      </axis>
    </joint>
    <link name="virt_Y5">
      <inertial>
        <inertia>
          <ixx>0.001</ixx>
          <iyy>0.001</iyy>
          <izz>0.001</izz>
          <ixy>0</ixy>
          <ixz>0</ixz>
          <iyz>0</iyz>
        </inertia>
        <mass>0.001</mass>
      </inertial>
      <pose>-3.500000 2.000000 3.500000 2.651635 1.243058 2.469927</pose>
    </link>
    <joint name="rev_Y5" type="revolute">
      <pose>0 0 0 2.651635 1.243058 2.469927</pose>
      <parent>virt_X5</parent>
      <child>virt_Y5</child>
      <axis>
        <xyz>0.200317 0.967949 0.151484</xyz>
        <limit>
          <effort>1000</effort>
          <velocity>10</velocity>
        </limit>
        <dynamics>
          <damping>0.01</damping>
        </dynamics>
      </axis>
    </joint>
    <joint name="cable5" type="prismatic">
      <pose>0 0 -0.326640 2.651635 1.243058 2.469927</pose>
      <parent>virt_Y5</parent>
      <child>cable5</child>
      <axis>
        <xyz>-0.946773 0.151484 0.284032</xyz>
        <limit>
          <lower>-4.931287864239929</lower>
          <upper>4.931287864239929</upper>
          <effort>10000</effort>
          <velocity>10</velocity>
        </limit>
        <dynamics>
          <damping>1</damping>
        </dynamics>
      </axis>
    </joint>
    <link name="virt_Xpf5">
      <inertial>
        <inertia>
          <ixx>0.001</ixx>
          <iyy>0.001</iyy>
          <izz>0.001</izz>
          <ixy>0</ixy>
          <ixz>0</ixz>
          <iyz>0</iyz>
        </inertia>
        <mass>0.001</mass>
      </inertial>
      <pose>1.500000 1.200000 2.000000 2.651635 1.243058 2.469927</pose>
    </link>
    <joint name="rev_Xpf5" type="revolute">
      <pose>0 0 0 2.651635 1.243058 2.469927</pose>
      <parent>platform</parent>
      <child>virt_Xpf5</child>
      <axis>
        <xyz>1 0 0</xyz>
        <limit>
          <effort>1000</effort>
          <velocity>10</velocity>
        </limit>
        <dynamics>
          <damping>0.01</damping>
        </dynamics>
      </axis>
    </joint>
    <link name="virt_Ypf5">
      <inertial>
        <inertia>
          <ixx>0.001</ixx>
          <iyy>0.001</iyy>
          <izz>0.001</izz>
          <ixy>0</ixy>
          <ixz>0</ixz>
          <iyz>0</iyz>
        </inertia>
        <mass>0.001</mass>
      </inertial>
      <pose>1.500000 1.200000 2.000000 2.651635 1.243058 2.469927</pose>
    </link>
    <joint name="rev_Ypf5" type="revolute">
      <pose>0 0 0 2.651635 1.243058 2.469927</pose>
      <parent>virt_Xpf5</parent>
      <child>virt_Ypf5</child>
      <axis>
        <xyz>0 1 0</xyz>
        <limit>
          <effort>1000</effort>
          <velocity>10</velocity>
        </limit>
        <dynamics>
          <damping>0.01</damping>
        </dynamics>
      </axis>
    </joint>
    <joint name="rev_Zpf5" type="revolute">
      <pose>0 0 0 2.651635 1.243058 2.469927</pose>
      <child>virt_Ypf5</child>
      <parent>cable5</parent>
      <axis>
        <xyz>0 0 1</xyz>
        <limit>
          <effort>1000</effort>
          <velocity>10</velocity>
        </limit>
        <dynamics>
          <damping>0.01</damping>
        </dynamics>
      </axis>
    </joint>
    <link name="cable6">
      <pose>4.942063 3.009444 4.581547 2.390664 -0.772607 -1.602202</pose>
      <visual name="visual">
        <geometry>
          <cylinder>
            <radius>0.005</radius>
            <length>9.862575728479857</length>
          </cylinder>
        </geometry>
        <material>
          <script>
            <uri>file://media/materials/scripts/kitchen.material</uri>
            <name>Gazebo/Black</name>
          </script>
        </material>
      </visual>
      <inertial>
        <inertia>
          <ixx>0.001</ixx>
          <iyy>0.001</iyy>
          <izz>0.001</izz>
          <ixy>0</ixy>
          <ixz>0</ixz>
          <iyz>0</iyz>
        </inertia>
        <mass>0.001</mass>
      </inertial>
    </link>
    <link name="virt_X6">
      <inertial>
        <inertia>
          <ixx>0.001</ixx>
          <iyy>0.001</iyy>
          <izz>0.001</izz>
          <ixy>0</ixy>
          <ixz>0</ixz>
          <iyz>0</iyz>
        </inertia>
        <mass>0.001</mass>
      </inertial>
      <pose>3.500000 2.000000 3.500000 2.390664 -0.772607 -1.602202</pose>
    </link>
    <joint name="rev_X6" type="revolute">
      <pose>0 0 0 2.390664 -0.772607 -1.602202</pose>
      <parent>frame</parent>
      <child>virt_X6</child>
      <axis>
        <xyz>-0.022486 -0.715740 0.698005</xyz>
        <limit>
          <effort>1000</effort>
          <velocity>10</velocity>
        </limit>
        <dynamics>
          <damping>0.01</damping>
        </dynamics>
      </axis>
    </joint>
    <link name="virt_Y6">
      <inertial>
        <inertia>
          <ixx>0.001</ixx>
          <iyy>0.001</iyy>
          <izz>0.001</izz>
          <ixy>0</ixy>
          <ixz>0</ixz>
          <iyz>0</iyz>
        </inertia>
        <mass>0.001</mass>
      </inertial>
      <pose>3.500000 2.000000 3.500000 2.390664 -0.772607 -1.602202</pose>
    </link>
    <joint name="rev_Y6" type="revolute">
      <pose>0 0 0 2.390664 -0.772607 -1.602202</pose>
      <parent>virt_X6</parent>
      <child>virt_Y6</child>
      <axis>
        <xyz>-0.715740 0.498982 0.488603</xyz>
        <limit>
          <effort>1000</effort>
          <velocity>10</velocity>
        </limit>
        <dynamics>
          <damping>0.01</damping>
        </dynamics>
      </axis>
    </joint>
    <joint name="cable6" type="prismatic">
      <pose>0 0 3.555613 2.390664 -0.772607 -1.602202</pose>
      <parent>virt_Y6</parent>
      <child>cable6</child>
      <axis>
        <xyz>0.698005 0.488603 0.523504</xyz>
        <limit>
          <lower>-4.931287864239929</lower>
          <upper>4.931287864239929</upper>
          <effort>10000</effort>
          <velocity>10</velocity>
        </limit>
        <dynamics>
          <damping>1</damping>
        </dynamics>
      </axis>
    </joint>
    <link name="virt_Xpf6">
      <inertial>
        <inertia>
          <ixx>0.001</ixx>
          <iyy>0.001</iyy>
          <izz>0.001</izz>
          <ixy>0</ixy>
          <ixz>0</ixz>
          <iyz>0</iyz>
        </inertia>
        <mass>0.001</mass>
      </inertial>
      <pose>1.500000 0.600000 2.000000 2.390664 -0.772607 -1.602202</pose>
    </link>
    <joint name="rev_Xpf6" type="revolute">
      <pose>0 0 0 2.390664 -0.772607 -1.602202</pose>
      <parent>platform</parent>
      <child>virt_Xpf6</child>
      <axis>
        <xyz>1 0 0</xyz>
        <limit>
          <effort>1000</effort>
          <velocity>10</velocity>
        </limit>
        <dynamics>
          <damping>0.01</damping>
        </dynamics>
      </axis>
    </joint>
    <link name="virt_Ypf6">
      <inertial>
        <inertia>
          <ixx>0.001</ixx>
          <iyy>0.001</iyy>
          <izz>0.001</izz>
          <ixy>0</ixy>
          <ixz>0</ixz>
          <iyz>0</iyz>
        </inertia>
        <mass>0.001</mass>
      </inertial>
      <pose>1.500000 0.600000 2.000000 2.390664 -0.772607 -1.602202</pose>
    </link>
    <joint name="rev_Ypf6" type="revolute">
      <pose>0 0 0 2.390664 -0.772607 -1.602202</pose>
      <parent>virt_Xpf6</parent>
      <child>virt_Ypf6</child>
      <axis>
        <xyz>0 1 0</xyz>
        <limit>
          <effort>1000</effort>
          <velocity>10</velocity>
        </limit>
        <dynamics>
          <damping>0.01</damping>
        </dynamics>
      </axis>
    </joint>
    <joint name="rev_Zpf6" type="revolute">
      <pose>0 0 0 2.390664 -0.772607 -1.602202</pose>
      <child>virt_Ypf6</child>
      <parent>cable6</parent>
      <axis>
        <xyz>0 0 1</xyz>
        <limit>
          <effort>1000</effort>
          <velocity>10</velocity>
        </limit>
        <dynamics>
          <damping>0.01</damping>
        </dynamics>
      </axis>
    </joint>
    <link name="cable7">
      <pose>4.445493 2.236373 4.061386 2.743070 -0.998484 -2.432275</pose>
      <visual name="visual">
        <geometry>
          <cylinder>
            <radius>0.005</radius>
            <length>9.862575728479857</length>
          </cylinder>
        </geometry>
        <material>
          <script>
            <uri>file://media/materials/scripts/kitchen.material</uri>
            <name>Gazebo/Black</name>
          </script>
        </material>
      </visual>
      <inertial>
        <inertia>
          <ixx>0.001</ixx>
          <iyy>0.001</iyy>
          <izz>0.001</izz>
          <ixy>0</ixy>
          <ixz>0</ixz>
          <iyz>0</iyz>
        </inertia>
        <mass>0.001</mass>
      </inertial>
    </link>
    <link name="virt_X7">
      <inertial>
        <inertia>
          <ixx>0.001</ixx>
          <iyy>0.001</iyy>
          <izz>0.001</izz>
          <ixy>0</ixy>
          <ixz>0</ixz>
          <iyz>0</iyz>
        </inertia>
        <mass>0.001</mass>
      </inertial>
      <pose>3.500000 2.000000 3.500000 2.743070 -0.998484 -2.432275</pose>
    </link>
    <joint name="rev_X7" type="revolute">
      <pose>0 0 0 2.743070 -0.998484 -2.432275</pose>
      <parent>frame</parent>
      <child>virt_X7</child>
      <axis>
        <xyz>-0.410952 -0.352738 0.840651</xyz>
        <limit>
          <effort>1000</effort>
          <velocity>10</velocity>
        </limit>
        <dynamics>
          <damping>0.01</damping>
        </dynamics>
      </axis>
    </joint>
    <link name="virt_Y7">
      <inertial>
        <inertia>
          <ixx>0.001</ixx>
          <iyy>0.001</iyy>
          <izz>0.001</izz>
          <ixy>0</ixy>
          <ixz>0</ixz>
          <iyz>0</iyz>
        </inertia>
        <mass>0.001</mass>
      </inertial>
      <pose>3.500000 2.000000 3.500000 2.743070 -0.998484 -2.432275</pose>
    </link>
    <joint name="rev_Y7" type="revolute">
      <pose>0 0 0 2.743070 -0.998484 -2.432275</pose>
      <parent>virt_X7</parent>
      <child>virt_Y7</child>
      <axis>
        <xyz>-0.352738 0.911815 0.210163</xyz>
        <limit>
          <effort>1000</effort>
          <velocity>10</velocity>
        </limit>
        <dynamics>
          <damping>0.01</damping>
        </dynamics>
      </axis>
    </joint>
    <joint name="cable7" type="prismatic">
      <pose>0 0 1.457030 2.743070 -0.998484 -2.432275</pose>
      <parent>virt_Y7</parent>
      <child>cable7</child>
      <axis>
        <xyz>0.840651 0.210163 0.499137</xyz>
        <limit>
          <lower>-4.931287864239929</lower>
          <upper>4.931287864239929</upper>
          <effort>10000</effort>
          <velocity>10</velocity>
        </limit>
        <dynamics>
          <damping>1</damping>
        </dynamics>
      </axis>
    </joint>
    <link name="virt_Xpf7">
      <inertial>
        <inertia>
          <ixx>0.001</ixx>
          <iyy>0.001</iyy>
          <izz>0.001</izz>
          <ixy>0</ixy>
          <ixz>0</ixz>
          <iyz>0</iyz>
        </inertia>
        <mass>0.001</mass>
      </inertial>
      <pose>0.300000 1.200000 1.600000 2.743070 -0.998484 -2.432275</pose>
    </link>
    <joint name="rev_Xpf7" type="revolute">
      <pose>0 0 0 2.743070 -0.998484 -2.432275</pose>
      <parent>platform</parent>
      <child>virt_Xpf7</child>
      <axis>
        <xyz>1 0 0</xyz>
        <limit>
          <effort>1000</effort>
          <velocity>10</velocity>
        </limit>
        <dynamics>
          <damping>0.01</damping>
        </dynamics>
      </axis>
    </joint>
    <link name="virt_Ypf7">
      <inertial>
        <inertia>
          <ixx>0.001</ixx>
          <iyy>0.001</iyy>
          <izz>0.001</izz>
          <ixy>0</ixy>
          <ixz>0</ixz>
          <iyz>0</iyz>
        </inertia>
        <mass>0.001</mass>
      </inertial>
      <pose>0.300000 1.200000 1.600000 2.743070 -0.998484 -2.432275</pose>
    </link>
    <joint name="rev_Ypf7" type="revolute">
      <pose>0 0 0 2.743070 -0.998484 -2.432275</pose>
      <parent>virt_Xpf7</parent>
      <child>virt_Ypf7</child>
      <axis>
        <xyz>0 1 0</xyz>
        <limit>
          <effort>1000</effort>
          <velocity>10</velocity>
        </limit>
        <dynamics>
          <damping>0.01</damping>
        </dynamics>
      </axis>
    </joint>
    <joint name="rev_Zpf7" type="revolute">
      <pose>0 0 0 2.743070 -0.998484 -2.432275</pose>
      <child>virt_Ypf7</child>
      <parent>cable7</parent>
      <axis>
        <xyz>0 0 1</xyz>
        <limit>
          <effort>1000</effort>
          <velocity>10</velocity>
        </limit>
        <dynamics>
          <damping>0.01</damping>
        </dynamics>
      </axis>
    </joint>
    <!-- 여기서부터 매니퓰레이터 -->
    <joint name='panda_base' type='fixed'>
      <pose relative_to='platform'>0.5 0 0.2 0 0 0</pose>
      <parent>platform</parent>
      <child>panda_link0</child>
    </joint>
    <link name='panda_link0'>
      <pose relative_to='panda_base'>0 0 0 0 -0 0</pose>
      <inertial>
        <pose>-0.025566 -2.9e-05 0.057332 0 -0 0</pose>
        <mass>2.9</mass>
        <inertia>
          <ixx>0.1</ixx>
          <ixy>0</ixy>
          <ixz>0</ixz>
          <iyy>0.1</iyy>
          <iyz>0</iyz>
          <izz>0.1</izz>
        </inertia>
      </inertial>
      <collision name='panda_link0_collision'>
        <pose>0 0 0 0 -0 0</pose>
        <geometry>
          <mesh>
            <scale>1 1 1</scale>
            <uri>model://meshes/collision/link0.stl</uri>
          </mesh>
        </geometry>
        <surface>
          <contact>
            <ode/>
          </contact>
          <friction>
            <ode>
              <mu>0.85</mu>
              <mu2>0.85</mu2>
            </ode>
          </friction>
        </surface>
      </collision>
      <visual name='panda_link0_visual'>
        <pose>0 0 0 0 -0 0</pose>
        <geometry>
          <mesh>
            <scale>1 1 1</scale>
            <uri>model://meshes/visual/link0.dae</uri>
          </mesh>
        </geometry>
      </visual>
    </link>
    <joint name='panda_joint1' type='revolute'>
      <pose relative_to='panda_link0'>0 0 0.333 0 -0 0</pose>
      <parent>panda_link0</parent>
      <child>panda_link1</child>
      <axis>
        <xyz>0 0 -1</xyz>
        <limit>
          <lower>-2.89725</lower>
          <upper>2.89725</upper>
          <effort>87</effort>
          <velocity>2.61799</velocity>
        </limit>
        <dynamics>
          <damping>21.75</damping>
          <friction>3.48</friction>
          <spring_reference>0</spring_reference>
          <spring_stiffness>0</spring_stiffness>
        </dynamics>
      </axis>
      <physics>
        <ode>
          <limit>
            <cfm>0</cfm>
            <erp>0.2</erp>
          </limit>
        </ode>
      </physics>
    </joint>
    <link name='panda_link1'>
      <pose relative_to='panda_joint1'>0 0 0 0 -0 0</pose>
      <inertial>
        <pose>-0 -0.032496 -0.067582 0 -0 0</pose>
        <mass>2.7</mass>
        <inertia>
          <ixx>0.1</ixx>
          <ixy>0</ixy>
          <ixz>0</ixz>
          <iyy>0.1</iyy>
          <iyz>0</iyz>
          <izz>0.1</izz>
        </inertia>
      </inertial>
      <collision name='panda_link1_collision'>
        <pose>0 0 0 0 -0 0</pose>
        <geometry>
          <mesh>
            <scale>1 1 1</scale>
            <uri>model://meshes/collision/link1.stl</uri>
          </mesh>
        </geometry>
        <surface>
          <contact>
            <ode/>
          </contact>
          <friction>
            <ode>
              <mu>0.85</mu>
              <mu2>0.85</mu2>
            </ode>
          </friction>
        </surface>
      </collision>
      <visual name='panda_link1_visual'>
        <pose>0 0 0 0 -0 0</pose>
        <geometry>
          <mesh>
            <scale>1 1 1</scale>
            <uri>model://meshes/visual/link1.dae</uri>
          </mesh>
        </geometry>
      </visual>
    </link>
    <joint name='panda_joint2' type='revolute'>
      <pose relative_to='panda_link1'>0 0 0 -1.5708 0 0</pose>
      <parent>panda_link1</parent>
      <child>panda_link2</child>
      <axis>
        <xyz>0 -1 0</xyz>
        <limit>
          <lower>-1.76278</lower>
          <upper>1.76278</upper>
          <effort>87</effort>
          <velocity>2.61799</velocity>
        </limit>
        <dynamics>
          <damping>21.75</damping>
          <friction>3.48</friction>
          <spring_reference>0</spring_reference>
          <spring_stiffness>0</spring_stiffness>
        </dynamics>
      </axis>
      <physics>
        <ode>
          <limit>
            <cfm>0</cfm>
            <erp>0.2</erp>
          </limit>
        </ode>
      </physics>
    </joint>
    <link name='panda_link2'>
      <pose relative_to='panda_joint2'>0 0 0 0 -0 0</pose>
      <inertial>
        <pose>0 -0.06861 0.032229 0 -0 0</pose>
        <mass>2.73</mass>
        <inertia>
          <ixx>0.1</ixx>
          <ixy>0</ixy>
          <ixz>0</ixz>
          <iyy>0.1</iyy>
          <iyz>0</iyz>
          <izz>0.1</izz>
        </inertia>
      </inertial>
      <collision name='panda_link2_collision'>
        <pose>0 0 0 0 -0 0</pose>
        <geometry>
          <mesh>
            <scale>1 1 1</scale>
            <uri>model://meshes/collision/link2.stl</uri>
          </mesh>
        </geometry>
        <surface>
          <contact>
            <ode/>
          </contact>
          <friction>
            <ode>
              <mu>0.85</mu>
              <mu2>0.85</mu2>
            </ode>
          </friction>
        </surface>
      </collision>
      <visual name='panda_link2_visual'>
        <pose>0 0 0 0 -0 0</pose>
        <geometry>
          <mesh>
            <scale>1 1 1</scale>
            <uri>model://meshes/visual/link2.dae</uri>
          </mesh>
        </geometry>
      </visual>
    </link>
    <joint name='panda_joint3' type='revolute'>
      <pose relative_to='panda_link2'>0 -0.316 0 1.5708 -0 0</pose>
      <parent>panda_link2</parent>
      <child>panda_link3</child>
      <axis>
        <xyz>0 0 -1</xyz>
        <limit>
          <lower>-2.89725</lower>
          <upper>2.89725</upper>
          <effort>87</effort>
          <velocity>2.61799</velocity>
        </limit>
        <dynamics>
          <damping>21.75</damping>
          <friction>3.48</friction>
          <spring_reference>0</spring_reference>
          <spring_stiffness>0</spring_stiffness>
        </dynamics>
      </axis>
      <physics>
        <ode>
          <limit>
            <cfm>0</cfm>
            <erp>0.2</erp>
          </limit>
        </ode>
      </physics>
    </joint>
    <link name='panda_link3'>
      <pose relative_to='panda_joint3'>0 0 0 0 -0 0</pose>
      <inertial>
        <pose>0.01 0.01 -0.05 0 -0 0</pose>
        <mass>2.04</mass>
        <inertia>
          <ixx>0.1</ixx>
          <ixy>0</ixy>
          <ixz>0</ixz>
          <iyy>0.1</iyy>
          <iyz>0</iyz>
          <izz>0.1</izz>
        </inertia>
      </inertial>
      <collision name='panda_link3_collision'>
        <pose>0 0 0 0 -0 0</pose>
        <geometry>
          <mesh>
            <scale>1 1 1</scale>
            <uri>model://meshes/collision/link3.stl</uri>
          </mesh>
        </geometry>
        <surface>
          <contact>
            <ode/>
          </contact>
          <friction>
            <ode>
              <mu>0.85</mu>
              <mu2>0.85</mu2>
            </ode>
          </friction>
        </surface>
      </collision>
      <visual name='panda_link3_visual'>
        <pose>0 0 0 0 -0 0</pose>
        <geometry>
          <mesh>
            <scale>1 1 1</scale>
            <uri>model://meshes/visual/link3.dae</uri>
          </mesh>
        </geometry>
      </visual>
    </link>
    <joint name='panda_joint4' type='revolute'>
      <pose relative_to='panda_link3'>0.0825 0 0 1.5708 0 0</pose>
      <parent>panda_link3</parent>
      <child>panda_link4</child>
      <axis>
        <xyz>0 1 0</xyz>
        <limit>
          <lower>-3.07178</lower>
          <upper>-0.0698132</upper>
          <effort>87</effort>
          <velocity>2.61799</velocity>
        </limit>
        <dynamics>
          <damping>21.75</damping>
          <friction>3.48</friction>
          <spring_reference>0</spring_reference>
          <spring_stiffness>0</spring_stiffness>
        </dynamics>
      </axis>
      <physics>
        <ode>
          <limit>
            <cfm>0</cfm>
            <erp>0.2</erp>
          </limit>
        </ode>
      </physics>
    </joint>
    <link name='panda_link4'>
      <pose relative_to='panda_joint4'>0 0 0 0 -0 0</pose>
      <inertial>
        <pose>-0.03 0.03 0.02 0 -0 0</pose>
        <mass>2.08</mass>
        <inertia>
          <ixx>0.1</ixx>
          <ixy>0</ixy>
          <ixz>0</ixz>
          <iyy>0.1</iyy>
          <iyz>0</iyz>
          <izz>0.1</izz>
        </inertia>
      </inertial>
      <collision name='panda_link4_collision'>
        <pose>0 0 0 0 -0 0</pose>
        <geometry>
          <mesh>
            <scale>1 1 1</scale>
            <uri>model://meshes/collision/link4.stl</uri>
          </mesh>
        </geometry>
        <surface>
          <contact>
            <ode/>
          </contact>
          <friction>
            <ode>
              <mu>0.85</mu>
              <mu2>0.85</mu2>
            </ode>
          </friction>
        </surface>
      </collision>
      <visual name='panda_link4_visual'>
        <pose>0 0 0 0 -0 0</pose>
        <geometry>
          <mesh>
            <scale>1 1 1</scale>
            <uri>model://meshes/visual/link4.dae</uri>
          </mesh>
        </geometry>
      </visual>
    </link>
    <joint name='panda_joint5' type='revolute'>
      <pose relative_to='panda_link4'>-0.0825 0.384 0 -1.5708 0 0</pose>
      <parent>panda_link4</parent>
      <child>panda_link5</child>
      <axis>
        <xyz>0 0 -1</xyz>
        <limit>
          <lower>-2.89725</lower>
          <upper>2.89725</upper>
          <effort>12</effort>
          <velocity>3.14159</velocity>
        </limit>
        <dynamics>
          <damping>3</damping>
          <friction>0.48</friction>
          <spring_reference>0</spring_reference>
          <spring_stiffness>0</spring_stiffness>
        </dynamics>
      </axis>
      <physics>
        <ode>
          <limit>
            <cfm>0</cfm>
            <erp>0.2</erp>
          </limit>
        </ode>
      </physics>
    </joint>
    <link name='panda_link5'>
      <pose relative_to='panda_joint5'>0 0 0 0 -0 0</pose>
      <inertial>
        <pose>0 0.04 -0.12 0 -0 0</pose>
        <mass>3</mass>
        <inertia>
          <ixx>0.1</ixx>
          <ixy>0</ixy>
          <ixz>0</ixz>
          <iyy>0.1</iyy>
          <iyz>0</iyz>
          <izz>0.1</izz>
        </inertia>
      </inertial>
      <collision name='panda_link5_collision'>
        <pose>0 0 0 0 -0 0</pose>
        <geometry>
          <mesh>
            <scale>1 1 1</scale>
            <uri>model://meshes/collision/link5.stl</uri>
          </mesh>
        </geometry>
        <surface>
          <contact>
            <ode/>
          </contact>
          <friction>
            <ode>
              <mu>0.85</mu>
              <mu2>0.85</mu2>
            </ode>
          </friction>
        </surface>
      </collision>
      <visual name='panda_link5_visual'>
        <pose>0 0 0 0 -0 0</pose>
        <geometry>
          <mesh>
            <scale>1 1 1</scale>
            <uri>model://meshes/visual/link5.dae</uri>
          </mesh>
        </geometry>
      </visual>
    </link>
    <joint name='panda_joint6' type='revolute'>
      <pose relative_to='panda_link5'>0 0 0 1.5708 -0 0</pose>
      <parent>panda_link5</parent>
      <child>panda_link6</child>
      <axis>
        <xyz>0 1 0</xyz>
        <limit>
          <lower>-0.0174533</lower>
          <upper>3.75246</upper>
          <effort>12</effort>
          <velocity>3.14159</velocity>
        </limit>
        <dynamics>
          <damping>3</damping>
          <friction>0.48</friction>
          <spring_reference>0</spring_reference>
          <spring_stiffness>0</spring_stiffness>
        </dynamics>
      </axis>
      <physics>
        <ode>
          <limit>
            <cfm>0</cfm>
            <erp>0.2</erp>
          </limit>
        </ode>
      </physics>
    </joint>
    <link name='panda_link6'>
      <pose relative_to='panda_joint6'>0 0 0 0 -0 0</pose>
      <inertial>
        <pose>0.04 0 0 0 -0 0</pose>
        <mass>1.3</mass>
        <inertia>
          <ixx>0.1</ixx>
          <ixy>0</ixy>
          <ixz>0</ixz>
          <iyy>0.1</iyy>
          <iyz>0</iyz>
          <izz>0.1</izz>
        </inertia>
      </inertial>
      <collision name='panda_link6_collision'>
        <pose>0 0 0 0 -0 0</pose>
        <geometry>
          <mesh>
            <scale>1 1 1</scale>
            <uri>model://meshes/collision/link6.stl</uri>
          </mesh>
        </geometry>
        <surface>
          <contact>
            <ode/>
          </contact>
          <friction>
            <ode>
              <mu>0.85</mu>
              <mu2>0.85</mu2>
            </ode>
          </friction>
        </surface>
      </collision>
      <visual name='panda_link6_visual'>
        <pose>0 0 0 0 -0 0</pose>
        <geometry>
          <mesh>
            <scale>1 1 1</scale>
            <uri>model://meshes/visual/link6.dae</uri>
          </mesh>
        </geometry>
      </visual>
    </link>
    <joint name='panda_joint7' type='revolute'>
      <pose relative_to='panda_link6'>0.088 0 0 1.5708 -0 0</pose>
      <parent>panda_link6</parent>
      <child>panda_link7</child>
      <axis>
        <xyz>0 0 1</xyz>
        <limit>
          <lower>-2.89725</lower>
          <upper>2.89725</upper>
          <effort>12</effort>
          <velocity>3.14159</velocity>
        </limit>
        <dynamics>
          <damping>3</damping>
          <friction>0.48</friction>
          <spring_reference>0</spring_reference>
          <spring_stiffness>0</spring_stiffness>
        </dynamics>
      </axis>
      <physics>
        <ode>
          <limit>
            <cfm>0</cfm>
            <erp>0.2</erp>
          </limit>
        </ode>
      </physics>
    </joint>
    <link name='panda_link7'>
      <pose relative_to='panda_joint7'>0 0 0 0 -0 0</pose>
      <inertial>
        <pose>0 0 0.08 0 -0 0</pose>
        <mass>1.01</mass>
        <inertia>
          <ixx>0.1</ixx>
          <ixy>0</ixy>
          <ixz>0</ixz>
          <iyy>0.1</iyy>
          <iyz>0</iyz>
          <izz>0.1</izz>
        </inertia>
      </inertial>
      <collision name='panda_link7_collision'>
        <pose>0 0 0 0 -0 0</pose>
        <geometry>
          <mesh>
            <scale>1 1 1</scale>
            <uri>model://meshes/collision/link7.stl</uri>
          </mesh>
        </geometry>
        <surface>
          <contact>
            <ode/>
          </contact>
          <friction>
            <ode>
              <mu>0.85</mu>
              <mu2>0.85</mu2>
            </ode>
          </friction>
        </surface>
      </collision>
      <collision name='panda_link7_fixed_joint_lump__panda_hand_collision_1'>
        <pose>0 0 0.107 0 0 -0.785398</pose>
        <geometry>
          <mesh>
            <scale>1 1 1</scale>
            <uri>model://meshes/collision/hand.stl</uri>
          </mesh>
        </geometry>
        <surface>
          <contact>
            <ode/>
          </contact>
          <friction>
            <ode>
              <mu>0.85</mu>
              <mu2>0.85</mu2>
            </ode>
          </friction>
        </surface>
      </collision>
      <visual name='panda_link7_visual'>
        <pose>0 0 0 0 -0 0</pose>
        <geometry>
          <mesh>
            <scale>1 1 1</scale>
            <uri>model://meshes/visual/link7.dae</uri>
          </mesh>
        </geometry>
      </visual>
      <visual name='panda_link7_fixed_joint_lump__panda_hand_visual_1'>
        <pose>0 0 0.107 0 0 -0.785398</pose>
        <geometry>
          <mesh>
            <scale>1 1 1</scale>
            <uri>model://meshes/visual/hand.dae</uri>
          </mesh>
        </geometry>
      </visual>
    </link>
    <joint name='panda_finger_joint1' type='prismatic'>
      <pose relative_to='panda_link7'>0 0 0.1654 0 0 -0.785398</pose>
      <parent>panda_link7</parent>
      <child>panda_leftfinger</child>
      <axis>
        <xyz>0 1 0</xyz>
        <limit>
          <lower>0</lower>
          <upper>0.04</upper>
          <effort>20</effort>
          <velocity>0.2</velocity>
        </limit>
        <dynamics>
          <damping>3</damping>
          <friction>0.4</friction>
          <spring_reference>0</spring_reference>
          <spring_stiffness>0</spring_stiffness>
        </dynamics>
      </axis>
      <physics>
        <ode>
          <limit>
            <cfm>0</cfm>
            <erp>0.2</erp>
          </limit>
        </ode>
      </physics>
    </joint>
    <link name='panda_leftfinger'>
      <pose relative_to='panda_finger_joint1'>0 0 0 0 -0 0</pose>
      <inertial>
        <pose>0 0.01 0.02 0 -0 0</pose>
        <mass>0.1</mass>
        <inertia>
          <ixx>0.1</ixx>
          <ixy>0</ixy>
          <ixz>0</ixz>
          <iyy>0.1</iyy>
          <iyz>0</iyz>
          <izz>0.1</izz>
        </inertia>
      </inertial>
      <collision name='panda_leftfinger_collision'>
        <pose>0 0 0 0 -0 0</pose>
        <geometry>
          <mesh>
            <scale>1 1 1</scale>
            <uri>model://meshes/collision/finger.stl</uri>
          </mesh>
        </geometry>
        <surface>
          <contact>
            <ode/>
          </contact>
          <friction>
            <ode>
              <mu>1.13</mu>
              <mu2>1.13</mu2>
            </ode>
          </friction>
        </surface>
      </collision>
      <visual name='panda_leftfinger_visual'>
        <pose>0 0 0 0 -0 0</pose>
        <geometry>
          <mesh>
            <scale>1 1 1</scale>
            <uri>model://meshes/visual/finger.dae</uri>
          </mesh>
        </geometry>
      </visual>
    </link>
    <joint name='panda_finger_joint2' type='prismatic'>
      <pose relative_to='panda_link7'>0 0 0.1654 0 0 -0.785398</pose>
      <parent>panda_link7</parent>
      <child>panda_rightfinger</child>
      <axis>
        <xyz>0 -1 0</xyz>
        <limit>
          <lower>0</lower>
          <upper>0.04</upper>
          <effort>20</effort>
          <velocity>0.2</velocity>
        </limit>
        <dynamics>
          <damping>3</damping>
          <friction>0.4</friction>
          <spring_reference>0</spring_reference>
          <spring_stiffness>0</spring_stiffness>
        </dynamics>
      </axis>
      <physics>
        <ode>
          <limit>
            <cfm>0</cfm>
            <erp>0.2</erp>
          </limit>
        </ode>
      </physics>
    </joint>
    <link name='panda_rightfinger'>
      <pose relative_to='panda_finger_joint2'>0 0 0 0 -0 0</pose>
      <inertial>
        <pose>-6e-06 0.002278 -0.027712 0 -0 3.14159</pose>
        <mass>0.1</mass>
        <inertia>
          <ixx>0.1</ixx>
          <ixy>0</ixy>
          <ixz>0</ixz>
          <iyy>0.1</iyy>
          <iyz>0</iyz>
          <izz>0.1</izz>
        </inertia>
      </inertial>
      <collision name='panda_rightfinger_collision'>
        <pose>0 0 0 0 -0 3.14159</pose>
        <geometry>
          <mesh>
            <scale>1 1 1</scale>
            <uri>model://meshes/collision/finger.stl</uri>
          </mesh>
        </geometry>
        <surface>
          <contact>
            <ode/>
          </contact>
          <friction>
            <ode>
              <mu>1.13</mu>
              <mu2>1.13</mu2>
            </ode>
          </friction>
        </surface>
      </collision>
      <visual name='panda_rightfinger_visual'>
        <pose>0 0 0 0 -0 3.14159</pose>
        <geometry>
          <mesh>
            <scale>1 1 1</scale>
            <uri>model://meshes/visual/finger.dae</uri>
          </mesh>
        </geometry>
      </visual>
    </link>
    <plugin filename="libcdpr_plugin.so" name="cdpr_plugin"/>
  </model>
</sdf>